#### 3.3. 예외 처리 (try, catch, throw)

예외 처리는 프로그램 실행 중 발생할 수 있는 오류 상황을 처리하는 메커니즘입니다. C++에서 예외 처리는 `try`, `catch`, `throw` 키워드를 사용하여 구현됩니다.

##### 예외 처리의 기본 구조

1. **try 블록**: 예외가 발생할 수 있는 코드를 포함합니다.
2. **throw 문**: 예외를 발생시킵니다.
3. **catch 블록**: 발생한 예외를 처리합니다.

###### 예외 처리 예제

```cpp
#include <iostream>
using namespace std;

int main() {
    try {
        int a = 10;
        int b = 0;
        if (b == 0) {
            throw "Division by zero condition!"; // 예외 발생
        }
        cout << "Result: " << a / b << endl;
    } catch (const char* msg) {
        cout << "Error: " << msg << endl; // 예외 처리
    }

    return 0;
}
```

이 예제에서 `try` 블록은 `b`가 0인 경우 예외를 발생시킵니다. `throw` 문은 문자열 예외를 던지며, `catch` 블록은 해당 예외를 받아 처리합니다.

##### 예외의 종류

C++에서는 다양한 타입의 예외를 던질 수 있습니다. 예외는 기본 타입일 수도 있고, 사용자 정의 예외 클래스일 수도 있습니다.

###### 기본 타입 예외

```cpp
#include <iostream>
using namespace std;

int main() {
    try {
        throw 20; // 정수 예외 발생
    } catch (int e) {
        cout << "Integer exception: " << e << endl;
    }

    return 0;
}
```

이 예제에서 정수 예외를 던지고, `catch` 블록에서 이를 처리합니다.

###### 사용자 정의 예외 클래스

사용자 정의 예외 클래스를 만들어 예외 정보를 더 풍부하게 제공할 수 있습니다.

```cpp
#include <iostream>
#include <string>
using namespace std;

class MyException {
public:
    string message;
    MyException(string msg) : message(msg) {}
};

int main() {
    try {
        throw MyException("Custom exception occurred!"); // 사용자 정의 예외 발생
    } catch (MyException &e) {
        cout << "Exception: " << e.message << endl; // 사용자 정의 예외 처리
    }

    return 0;
}
```

이 예제에서 `MyException` 클래스는 예외 메시지를 포함하며, `throw` 문을 통해 사용자 정의 예외를 던지고, `catch` 블록에서 이를 처리합니다.

##### 다중 catch 블록

여러 타입의 예외를 처리하려면 다중 `catch` 블록을 사용할 수 있습니다.

```cpp
#include <iostream>
using namespace std;

int main() {
    try {
        throw 10.5; // double 예외 발생
    } catch (int e) {
        cout << "Integer exception: " << e << endl;
    } catch (double e) {
        cout << "Double exception: " << e << endl;
    }

    return 0;
}
```

이 예제에서 `double` 타입의 예외를 던지고, 해당 예외를 처리하는 `catch` 블록이 호출됩니다.

##### 예외의 다시 던지기

`catch` 블록에서 예외를 다시 던질 수 있습니다. 이를 통해 예외를 상위 호출자에게 전달할 수 있습니다.

```cpp
#include <iostream>
using namespace std;

void func() {
    try {
        throw 100; // 예외 발생
    } catch (int e) {
        cout << "Exception caught in func: " << e << endl;
        throw; // 예외 다시 던지기
    }
}

int main() {
    try {
        func();
    } catch (int e) {
        cout << "Exception caught in main: " << e << endl;
    }

    return 0;
}
```

이 예제에서 `func` 함수는 예외를 던지고, `catch` 블록에서 이를 다시 던집니다. `main` 함수에서 최종적으로 예외를 처리합니다.

#### 요약

- **try 블록**: 예외가 발생할 수 있는 코드를 포함합니다.
- **throw 문**: 예외를 발생시킵니다.
- **catch 블록**: 발생한 예외를 처리합니다.
- **다중 catch 블록**: 여러 타입의 예외를 처리할 수 있습니다.
- **예외의 다시 던지기**: `catch` 블록에서 예외를 다시 던질 수 있습니다.
- **사용자 정의 예외 클래스**: 예외 정보를 더 풍부하게 제공할 수 있습니다.
